Workbook

Sheet Lisez-moi
A1: Bonne Mère 90 couches sur silice — dossier de réalisation pour Helios 800 et OMS 5100 (généré par CERTUS)
A3: Ordre des opérations : du substrat vers l'air. Op 1 à 90 : couches 1 à 90 sur la pièce ET le témoin. Pas de précouche.
A4: Contrôle Optique : arrêter quand T témoin, à λ de contrôle, atteint le niveau d'arrêt (onglet Stratégie), après avoir franchi le nombre
A5: de points tournants indiqué, dans le sens indiqué. Contrôle Rate : arrêter au temps = épaisseur / vitesse (quartz ou temps) ;
A6: pendant une couche Rate le monochromateur reste sur la dernière λ optique : le signal attendu est donné à cette λ.
A7: Signaux : T du témoin (face arrière de la silice incluse), à λ de contrôle, sans moyenne de fente ni bruit, pour l'empilement nominal.
A8: Le signal réel s'en écarte dès qu'une couche précédente s'écarte de son nominal : suivre le niveau d'arrêt, pas l'horloge.
A9: Temps : calculés par Excel à partir des vitesses de l'onglet Paramètres (cellules jaunes, valeurs PROVISOIRES à remplacer).
A10: QWOT à 600 nm : 4·n(600)·d / 600. Épaisseur optique de la règle Rate : n(550)·d.
A11: Spectres finaux : T à achèvement de la pièce (90 couches), théorique, sans erreur ; le témoin est identique (pas de précouche).
A12: Points tournants : extrema de T(d) dans la couche, comptés sur la courbe calculée (pas 0,1 nm), jamais déduits du QWOT.
A13: Hypothèses du modèle de performance : incertitude d'indice ±0,010, bruit 0,025/0,05/0,10 % T, fente 2 nm ; dérive de la source non modélisée.
... A16: Sources (sha256, 16 premiers caractères) : best_design_needle_swap_90_nominal.json e7a9e92b971038e0 ; modelam_s077_sapphire_rule.json c2ed9471a1261e87 ; cible_retenue_601points.csv a6a758362b38d9b1

Sheet Graphiques
A1: Graphiques (images). Temps calculés avec les vitesses PROVISOIRES 0,30 nm/s (H) et 0,50 nm/s (L) ; les graphiques natifs des onglets Signaux et Spectres finaux suivent les vitesses saisies.

Sheet Paramètres
A1: Paramètre | B1: Valeur | C1: Unité | D1: Remarque
A2: Machine | B2: Helios 800 (pulvérisation), contrôle optique OMS 5100
A3: Vitesse de dépôt H (Nb2O5) | B3: 0.3 | C3: nm/s | D3: À RENSEIGNER : valeur provisoire, pilote toutes les colonnes de temps
A4: Vitesse de dépôt L (SiO2) | B4: 0.5 | C4: nm/s | D4: À RENSEIGNER : valeur provisoire, pilote toutes les colonnes de temps
A5: Matériau H | B5: H800-Nb2O5
A6: Matériau L | B6: H800-SiO2
A7: Substrat (pièce et témoin) | B7: Silice fondue (CERTUS id 0) | D7: face arrière incluse dans les signaux
A8: Indice de la silice à 450 nm | B8: 1.465566 | D8: table complète : onglet Indices
A9: Indice de la silice à 550 nm | B9: 1.459911
A10: Indice de la silice à 600 nm | B10: 1.458038
A11: Longueur d'onde de référence des QWOT | B11: 600 | C11: nm | D11: QWOT = 4·n(600)·d / 600
A12: Nombre d'opérations | B12: 90 | D12: 90 couches, pièce et témoin, sans précouche
A13: Couches en Optique | B13: 75 | D13: 83 %
A14: Couches en Rate | B14: 15 | D14: règle : épaisseur optique n(550)·d ≤ 50 nm, aucune avant la couche 10
A15: Témoin | B15: 1 seul, jamais changé | D15: reçoit les 90 couches
A16: Précouches | B16: aucune | D16: première couche 99,6 nm
A17: Plage de monitoring | B17: 430–900 | C17: nm
A18: Fente du monochromateur | B18: 2 | C18: nm | D18: fixe ; les signaux ci-joints sont calculés sans moyenne de fente
A19: Incertitude d'indice supposée | B19: 0.01 | C19: unité d'indice | D19: écart systématique par matériau, uniforme
A20: Bruit photométrique nominal | B20: 0.05 | C20: % T | D20: niveaux évalués : 0,025 / 0,05 / 0,10
A21: Hystérésis de lecture des points tournants | B21: 1.66 | C21: × bruit
A22: Performance attendue (modèle) | B22: SEEL P95 0,2608 nm ; 0 arrêt au holdout (3 x 1 000 tirages par bruit), 1 arrêt sur 9 000 aux graines de confirmation | D22: graines neuves ; dérive de la source NON modélisée
A23: RMSE nominal pièce / cible (recalculé ici) | B23: 1.5495 | C23: pp | D23: design : 1.5495 pp
A24: Stratégie | B24: STRAT graine 77 + affinage apparié sous la règle du saphir

Sheet Stratégie
A1: Op | B1: Couche pièce | C1: Rôle | D1: Matériau | E1: Épaisseur mécanique (nm) | F1: n(600) | G1: k(600) | H1: QWOT à 600 nm | I1: n(550) | J1: Épaisseur optique n(550)·d (nm) | K1: Mode de contrôle | L1: λ du monochromateur (nm) (Rate : dernière λ optique) | M1: n couche (λ monochromateur) | N1: T témoin début (%) | O1: T témoin arrêt = niveau d'arrêt (%) | P1: Sens du signal à l'arrêt | Q1: Pente à l'arrêt (%T/nm) | R1: Points tournants franchis | S1: Points tournants (épaisseur nm ; T %) | T1: Durée (s) | U1: Temps cumulé fin (s) | V1: n silice (λ monochromateur)
A2: 1 | B2: 1 | C2: couche pièce | D2: H800-Nb2O5 | E2: 99.578899 | F2: 2.332333 | G2: 0 | H2: 1.548341 | I2: 2.357884 | J2: 234.79549 | K2: Optique | L2: 532 | M2: 2.369331 | N2: 93.226766 | O2: 88.353199 | P2: montant | Q2: 0.69849145 | R2: 1 | S2: 56.1 ; 64.014 | T2: =E2/Paramètres!$B$3 | U2: =SUM($T$2:T2) | V2: 1.4607063
A3: 2 | B3: 2 | C3: couche pièce | D3: H800-SiO2 | E3: 84.849668 | F3: 1.484484 | G3: 3.25e-05 | H3: 0.83971983 | I3: 1.486816 | J3: 126.15584 | K3: Optique | L3: 500 | M3: 1.489902 | N3: 92.264443 | O3: 92.358556 | P3: descendant | Q3: -0.096832812 | R3: 1 | S3: 42.9 ; 95.015 | T3: =E3/Paramètres!$B$4 | U3: =SUM($T$2:T3) | V3: 1.4623265
A4: 3 | B4: 3 | C4: couche pièce | D4: H800-Nb2O5 | E4: 16.728134 | F4: 2.332333 | G4: 0 | H4: 0.26010386 | I4: 2.357884 | J4: 39.443 | K4: Optique | L4: 704 | M4: 2.297779 | N4: 91.179602 | O4: 87.897242 | P4: descendant | Q4: -0.94183876 | R4: 1 | S4: 6.3 ; 93.195 | T4: =E4/Paramètres!$B$3 | U4: =SUM($T$2:T4) | V4: 1.4552019
A5: 4 | B5: 4 | C5: couche pièce | D5: H800-SiO2 | E5: 31.011426 | F5: 1.484484 | G5: 3.25e-05 | H5: 0.30690643 | I5: 1.486816 | J5: 46.108284 | K5: Optique | L5: 700 | M5: 1.4812505 | N5: 87.476796 | O5: 77.74849 | P5: descendant | Q5: -0.31030992 | R5: 0 | T5: =E5/Paramètres!$B$4 | U5: =SUM($T$2:T5) | V5: 1.4552925
A6: 5 | B6: 5 | C6: couche pièce | D6: H800-Nb2O5 | E6: 51.100427 | F6: 2.332333 | G6: 0 | H6: 0.79455475 | I6: 2.357884 | J6: 120.48888 | K6: Optique | L6: 900 | M6: 2.264553 | N6: 94.708804 | O6: 58.810038 | P6: descendant | Q6: -0.66793752 | R6: 0 | T6: =E6/Paramètres!$B$3 | U6: =SUM($T$2:T6) | V6: 1.451754
A7: 6 | B7: 6 | C7: couche pièce | D7: H800-SiO2 | E7: 162.96643 | F7: 1.484484 | G7: 3.25e-05 | H7: 1.6128071 | I7: 1.486816 | J7: 242.3011 | K7: Optique | L7: 665 | M7: 1.482215 | N7: 51.606133 | O7: 61.591189 | P7: descendant | Q7: -0.36505718 | R7: 1 | S7: 104.6 ; 79.532 | T7: =E7/Paramètres!$B$4 | U7: =SUM($T$2:T7) | V7: 1.4561388
A8: 7 | B8: 7 | C8: couche pièce | D8: H800-Nb2O5 | E8: 84.554768 | F8: 2.332333 | G8: 0 | H8: 1.3147325 | I8: 2.357884 | J8: 199.37033 | K8: Optique | L8: 720 | M8: 2.293902 | N8: 66.514719 | O8: 29.046347 | P8: montant | Q8: 0.3327227 | R8: 1 | S8: 63.3 ; 25.704 | T8: =E8/Paramètres!$B$3 | U8: =SUM($T$2:T8) | V8: 1.454851
A9: 8 | B9: 8 | C9: couche pièce | D9: H800-SiO2 | E9: 137.9369 | F9: 1.484484 | G9: 3.25e-05 | H9: 1.3651008 | I9: 1.486816 | J9: 205.08679 | K9: Optique | L9: 750 | M9: 1.480102 | N9: 24.85968 | O9: 42.774322 | P9: descendant | Q9: -0.23786648 | R9: 1 | S9: 114.2 ; 45.896 | T9: =E9/Paramètres!$B$4 | U9: =SUM($T$2:T9) | V9: 1.4542367
A10: 9 | B10: 9 | C10: couche pièce | D10: H800-Nb2O5 | E10: 77.284148 | F10: 2.332333 | G10: 0 | H10: 1.2016825 | I10: 2.357884 | J10: 182.22706 | K10: Optique | L10: 690 | M10: 2.301422 | N10: 46.517264 | O10: 26.903824 | P10: montant | Q10: 0.43904094 | R10: 1 | S10: 50.7 ; 21.648 | T10: =E10/Paramètres!$B$3 | U10: =SUM($T$2:T10) | V10: 1.4555241
A11: 10 | B11: 10 | C11: couche pièce | D11: H800-SiO2 | E11: 134.73431 | F11: 1.484484 | G11: 3.25e-05 | H11: 1.3334062 | I11: 1.486816 | J11: 200.32512 | K11: Optique | L11: 616 | M11: 1.483857 | N11: 80.382134 | O11: 92.600025 | P11: descendant | Q11: -0.21383638 | R11: 2 | S11: 0.2 ; 80.382 | 104.0 ; 96.286 | T11: =E11/Paramètres!$B$4 | U11: =SUM($T$2:T11) | V11: 1.4575227
A12: 11 | B12: 11 | C12: couche pièce | D12: H800-Nb2O5 | E12: 82.422165 | F12: 2.332333 | G12: 0 | H12: 1.2815729 | I12: 2.357884 | J12: 194.3419 | K12: Optique | L12: 611 | M12: 2.3276865 | N12: 90.027372 | O12: 59.399865 | P12: montant | Q12: 0.8565844 | R12: 1 | S12: 54.6 ; 48.008 | T12: =E12/Paramètres!$B$3 | U12: =SUM($T$2:T12) | V12: 1.4576799
A13: 12 | B13: 12 | C13: couche pièce | D13: H800-SiO2 | E13: 132.63495 | F13: 1.484484 | G13: 3.25e-05 | H13: 1.3126298 | I13: 1.486816 | J13: 197.20377 | K13: Optique | L13: 624 | M13: 1.483562 | N13: 66.020596 | O13: 77.277235 | P13: descendant | Q13: -0.38521806 | R13: 1 | S13: 85.8 ; 89.907 | T13: =E13/Paramètres!$B$4 | U13: =SUM($T$2:T13) | V13: 1.457278
A14: 13 | B14: 13 | C14: couche pièce | D14: H800-Nb2O5 | E14: 87.10062 | F14: 2.332333 | G14: 0 | H14: 1.3543177 | I14: 2.357884 | J14: 205.37316 | K14: Optique | L14: 620 | M14: 2.324096 | N14: 73.026047 | O14: 65.725016 | P14: montant | Q14: 1.3367674 | R14: 1 | S14: 46.2 ; 40.506 | T14: =E14/Paramètres!$B$3 | U14: =SUM($T$2:T14) | V14: 1.4573994
A15: 14 | B15: 14 | C15: couche pièce | D15: H800-SiO2 | E15: 156.09644 | F15: 1.484484 | G15: 3.25e-05 | H15: 1.5448178 | I15: 1.486816 | J15: 232.08669 | K15: Optique | L15: 600 | M15: 1.484484 | N15: 89.118286 | O15: 75.103436 | P15: montant | Q15: 0.20597137 | R15: 2 | S15: 28.4 ; 93.999 | 129.4 ; 72.295 | T15: =E15/Paramètres!$B$4 | U15: =SUM($T$2:T15) | V15: 1.4580377
A16: 15 | B16: 15 | C16: couche pièce | D16: H800-Nb2O5 | E16: 229.00294 | F16: 2.332333 | G16: 0 | H16: 3.5607407 | I16: 2.357884 | J16: 539.96236 | K16: Optique | L16: 486 | M16: 2.406468 | N16: 91.872847 | O16: 71.925749 | P16: descendant | Q16: -0.71516772 | R16: 4 | S16: 47.2 ; 64.466 | 97.7 ; 92.288 | 148.2 ; 64.466 | 198.7 ; 92.288 | T16: =E16/Paramètres!$B$3 | U16: =SUM($T$2:T16) | V16: 1.4631345
A17: 16 | B17: 16 | C17: couche pièce | D17: H800-SiO2 | E17: 13.07276 | F17: 1.484484 | G17: 3.25e-05 | H17: 0.12937536 | I17: 1.486816 | J17: 19.436789 | K17: Rate | L17: 486 | M17: 1.4909465 | N17: 71.925749 | O17: 70.604256 | P17: descendant | Q17: -0.018756919 | R17: 0 | T17: =E17/Paramètres!$B$4 | U17: =SUM($T$2:T17) | V17: 1.4631345
A18: 17 | B18: 17 | C18: couche pièce | D18: H800-Nb2O5 | E18: 116.96088 | F18: 2.332333 | G18: 0 | H18: 1.8186115 | I18: 2.357884 | J18: 275.7802 | K18: Optique | L18: 460 | M18: 2.434518 | N18: 68.035552 | O18: 77.470807 | P18: montant | Q18: 0.71010359 | R18: 2 | S18: 46.0 ; 89.731 | 93.2 ; 68.006 | T18: =E18/Paramètres!$B$3 | U18: =SUM($T$2:T18) | V18: 1.4648327
A19: 18 | B19: 18 | C19: couche pièce | D19: H800-SiO2 | E19: 166.72076 | F19: 1.484484 | G19: 3.25e-05 | H19: 1.649962 | I19: 1.486816 | J19: 247.88309 | K19: Optique | L19: 550 | M19: 1.486816 | N19: 76.594727 | O19: 76.801206 | P19: descendant | Q19: -0.091596266 | R19: 1 | S19: 84.7 ; 95.405 | T19: =E19/Paramètres!$B$4 | U19: =SUM($T$2:T19) | V19: 1.4599109
A20: 19 | B20: 19 | C20: couche pièce | D20: H800-Nb2O5 | E20: 118.37264 | F20: 2.332333 | G20: 0 | H20: 1.8405628 | I20: 2.357884 | J20: 279.10895 | K20: Optique | L20: 560 | M20: 2.352102 | N20: 85.450634 | O20: 86.006215 | P20: descendant | Q20: -0.82242 | R20: 2 | S20: 42.1 ; 62.229 | 101.6 ; 94.104 | T20: =E20/Paramètres!$B$3 | U20: =SUM($T$2:T20) | V20: 1.4594995
A21: 20 | B21: 20 | C21: couche pièce | D21: H800-SiO2 | E21: 18.644447 | F21: 1.484484 | G21: 3.25e-05 | H21: 0.18451589 | I21: 1.486816 | J21: 27.720863 | K21: Rate | L21: 560 | M21: 1.4862985 | N21: 86.006215 | O21: 82.724538 | P21: descendant | Q21: -0.12453761 | R21: 0 | T21: =E21/Paramètres!$B$4 | U21: =SUM($T$2:T21) | V21: 1.4594995
A22: 21 | B22: 21 | C22: couche pièce | D22: H800-Nb2O5 | E22: 208.12058 | F22: 2.332333 | G22: 0 | H22: 3.2360434 | I22: 2.357884 | J22: 490.72419 | K22: Optique | L22: 480 | M22: 2.41239 | N22: 92.121638 | O22: 89.524382 | P22: descendant | Q22: -0.59371436 | R22: 5 | S22: 0.8 ; 92.145 | 50.5 ; 64.48 | 100.3 ; 92.145 | 150.0 ; 64.48 | 199.8 ; 92.145 | T22: =E22/Paramètres!$B$3 | U22: =SUM($T$2:T22) | V22: 1.4635022
A23: 22 | B23: 22 | C23: couche pièce | D23: H800-SiO2 | E23: 13.03421 | F23: 1.484484 | G23: 3.25e-05 | H23: 0.12899384 | I23: 1.486816 | J23: 19.379472 | K23: Rate | L23: 480 | M23: 1.491423 | N23: 89.524382 | O23: 87.882146 | P23: descendant | Q23: -0.096495894 | R23: 0 | T23: =E23/Paramètres!$B$4 | U23: =SUM($T$2:T23) | V23: 1.4635022
A24: 23 | B24: 23 | C24: couche pièce | D24: H800-Nb2O5 | E24: 222.62387 | F24: 2.332333 | G24: 0 | H24: 3.4615534 | I24: 2.357884 | J24: 524.92127 | K24: Optique | L24: 450 | M24: 2.447206 | N24: 77.682794 | O24: 66.160745 | P24: descendant | Q24: -1.4103436 | R24: 5 | S24: 15.7 ; 96.167 | 61.7 ; 50.446 | 107.7 ; 96.167 | 153.7 ; 50.446 | 199.6 ; 96.167 | T24: =E24/Paramètres!$B$3 | U24: =SUM($T$2:T24) | V24: 1.4655657
A25: 24 | B25: 24 | C25: couche pièce | D25: H800-SiO2 | E25: 7.7586093 | F25: 1.484484 | G25: 3.25e-05 | H25: 0.076783542 | I25: 1.486816 | J25: 11.535624 | K25: Rate | L25: 450 | M25: 1.4941095 | N25: 66.160745 | O25: 63.913188 | P25: descendant | Q25: -0.23022525 | R25: 0 | T25: =E25/Paramètres!$B$4 | U25: =SUM($T$2:T25) | V25: 1.4655657
A26: 25 | B26: 25 | C26: couche pièce | D26: H800-Nb2O5 | E26: 230.60351 | F26: 2.332333 | G26: 0 | H26: 3.5856278 | I26: 2.357884 | J26: 543.73632 | K26: Optique | L26: 560 | M26: 2.352102 | N26: 82.513982 | O26: 76.591263 | P26: montant | Q26: 0.76137643 | R26: 4 | S26: 21.4 ; 93.376 | 80.9 ; 63.967 | 140.4 ; 93.376 | 200.0 ; 63.967 | T26: =E26/Paramètres!$B$3 | U26: =SUM($T$2:T26) | V26: 1.4594995
A27: 26 | B27: 26 | C27: couche pièce | D27: H800-SiO2 | E27: 167.24555 | F27: 1.484484 | G27: 3.25e-05 | H27: 1.6551556 | I27: 1.486816 | J27: 248.66335 | K27: Optique | L27: 540 | M27: 1.4873635 | N27: 75.415274 | O27: 71.90742 | P27: montant | Q27: 0.17853235 | R27: 2 | S27: 58.8 ; 93.149 | 149.6 ; 70.316 | T27: =E27/Paramètres!$B$4 | U27: =SUM($T$2:T27) | V27: 1.4603436
A28: 27 | B28: 27 | C28: couche pièce | D28: H800-Nb2O5 | E28: 26.726427 | F28: 2.332333 | G28: 0 | H28: 0.41556619 | I28: 2.357884 | J28: 63.017815 | K28: Optique | L28: 530 | M28: 2.370694 | N28: 90.048937 | O28: 83.681943 | P28: descendant | Q28: -0.69788432 | R28: 1 | S28: 7.9 ; 91.658 | T28: =E28/Paramètres!$B$3 | U28: =SUM($T$2:T28) | V28: 1.4607995
A29: 28 | B29: 28 | C29: couche pièce | D29: H800-SiO2 | E29: 175.10332 | F29: 1.484484 | G29: 3.25e-05 | H29: 1.7329205 | I29: 1.486816 | J29: 260.34642 | K29: Optique | L29: 580 | M29: 1.4853435 | N29: 45.812912 | O29: 49.963671 | P29: descendant | Q29: -0.29820668 | R29: 2 | S29: 12.7 ; 45.087 | 110.3 ; 73.222 | T29: =E29/Paramètres!$B$4 | U29: =SUM($T$2:T29) | V29: 1.4587346
A30: 29 | B30: 29 | C30: couche pièce | D30: H800-Nb2O5 | E30: 297.20543 | F30: 2.332333 | G30: 0 | H30: 4.6212135 | I30: 2.357884 | J30: 700.77593 | K30: Optique | L30: 530 | M30: 2.370694 | N30: 84.24483 | O30: 82.475892 | P30: montant | Q30: 0.78578082 | R30: 5 | S30: 38.0 ; 65.166 | 93.9 ; 92.478 | 149.7 ; 65.166 | 205.6 ; 92.478 | 261.5 ; 65.166 | T30: =E30/Paramètres!$B$3 | U30: =SUM($T$2:T30) | V30: 1.4607995
A31: 30 | B31: 30 | C31: couche pièce | D31: H800-SiO2 | E31: 293.24138 | F31: 1.484484 | G31: 3.25e-05 | H31: 2.902081 | I31: 1.486816 | J31: 435.99598 | K31: Optique | L31: 580 | M31: 1.4853435 | N31: 40.35635 | O31: 61.865584 | P31: descendant | Q31: -0.38238178 | R31: 3 | S31: 78.5 ; 65.986 | 176.2 ; 38.834 | 273.8 ; 65.974 | T31: =E31/Paramètres!$B$4 | U31: =SUM($T$2:T31) | V31: 1.4587346
A32: 31 | B32: 31 | C32: couche pièce | D32: H800-Nb2O5 | E32: 221.36704 | F32: 2.332333 | G32: 0 | H32: 3.442011 | I32: 2.357884 | J32: 521.95781 | K32: Optique | L32: 600 | M32: 2.332333 | N32: 58.720686 | O32: 21.800246 | P32: montant | Q32: 0.5556046 | R32: 3 | S32: 64.3 ; 15.195 | 128.7 ; 58.721 | 193.0 ; 15.195 | T32: =E32/Paramètres!$B$3 | U32: =SUM($T$2:T32) | V32: 1.4580377
A33: 32 | B33: 32 | C33: couche pièce | D33: H800-SiO2 | E33: 54.21996 | F33: 1.484484 | G33: 3.25e-05 | H33: 0.53659109 | I33: 1.486816 | J33: 80.615104 | K33: Optique | L33: 500 | M33: 1.489902 | N33: 62.541287 | O33: 58.061325 | P33: montant | Q33: 0.26778001 | R33: 1 | S33: 33.6 ; 55.286 | T33: =E33/Paramètres!$B$4 | U33: =SUM($T$2:T33) | V33: 1.4623265
A34: 33 | B34: 33 | C34: couche pièce | D34: H800-Nb2O5 | E34: 105.74367 | F34: 2.332333 | G34: 0 | H34: 1.6441963 | I34: 2.357884 | J34: 249.3313 | K34: Optique | L34: 600 | M34: 2.332333 | N34: 35.87102 | O34: 15.652862 | P34: montant | Q34: 0.52481776 | R34: 2 | S34: 6.4 ; 38.882 | 70.7 ; 8.741 | T34: =E34/Paramètres!$B$3 | U34: =SUM($T$2:T34) | V34: 1.4580377
A35: 34 | B35: 34 | C35: couche pièce | D35: H800-SiO2 | E35: 172.27826 | F35: 1.484484 | G35: 3.25e-05 | H35: 1.7049621 | I35: 1.486816 | J35: 256.14607 | K35: Optique | L35: 580 | M35: 1.4853435 | N35: 44.66543 | O35: 35.960351 | P35: montant | Q35: 0.31042593 | R35: 2 | S35: 31.9 ; 53.454 | 129.6 ; 29.467 | T35: =E35/Paramètres!$B$4 | U35: =SUM($T$2:T35) | V35: 1.4587346
A36: 35 | B36: 35 | C36: couche pièce | D36: H800-Nb2O5 | E36: 115.73223 | F36: 2.332333 | G36: 0 | H36: 1.7995074 | I36: 2.357884 | J36: 272.88318 | K36: Optique | L36: 560 | M36: 2.352102 | N36: 84.246635 | O36: 79.698962 | P36: montant | Q36: 1.3920874 | R36: 2 | S36: 14.8 ; 96.236 | 74.4 ; 48.678 | T36: =E36/Paramètres!$B$3 | U36: =SUM($T$2:T36) | V36: 1.4594995
A37: 36 | B37: 36 | C37: couche pièce | D37: H800-SiO2 | E37: 318.45413 | F37: 1.484484 | G37: 3.25e-05 | H37: 3.1516004 | I37: 1.486816 | J37: 473.4827 | K37: Optique | L37: 600 | M37: 1.484484 | N37: 12.450993 | O37: 24.252489 | P37: descendant | Q37: -0.14751409 | R37: 4 | S37: 2.2 ; 12.443 | 103.3 ; 25.28 | 204.3 ; 12.442 | 305.4 ; 25.275 | T37: =E37/Paramètres!$B$4 | U37: =SUM($T$2:T37) | V37: 1.4580377
A38: 37 | B38: 37 | C38: couche pièce | D38: H800-Nb2O5 | E38: 86.552697 | F38: 2.332333 | G38: 0 | H38: 1.3457981 | I38: 2.357884 | J38: 204.08122 | K38: Optique | L38: 590 | M38: 2.336829 | N38: 47.656425 | O38: 27.376892 | P38: montant | Q38: 0.88345731 | R38: 1 | S38: 51.2 ; 15.347 | T38: =E38/Paramètres!$B$3 | U38: =SUM($T$2:T38) | V38: 1.4583783
A39: 38 | B39: 38 | C39: couche pièce | D39: H800-SiO2 | E39: 55.505035 | F39: 1.484484 | G39: 3.25e-05 | H39: 0.54930891 | I39: 1.486816 | J39: 82.525775 | K39: Optique | L39: 440 | M39: 1.4951335 | N39: 57.511815 | O39: 72.461029 | P39: descendant | Q39: -0.52738608 | R39: 1 | S39: 40.1 ; 76.937 | T39: =E39/Paramètres!$B$4 | U39: =SUM($T$2:T39) | V39: 1.4663498
A40: 39 | B40: 39 | C40: couche pièce | D40: H800-Nb2O5 | E40: 127.86633 | F40: 2.332333 | G40: 0 | H40: 1.9881791 | I40: 2.357884 | J40: 301.49398 | K40: Optique | L40: 500 | M40: 2.393737 | N40: 79.10519 | O40: 60.561082 | P40: descendant | Q40: -2.0448075 | R40: 3 | S40: 7.2 ; 86.186 | 59.4 ; 29.434 | 111.7 ; 86.186 | T40: =E40/Paramètres!$B$3 | U40: =SUM($T$2:T40) | V40: 1.4623265
...

Sheet Signaux
A1: Op | B1: Mode | C1: Matériau | D1: λ du monochromateur (nm) | E1: Épaisseur déposée dans la couche (nm) | F1: T témoin attendue (%) | G1: Temps dans la couche (s) | H1: Temps cumulé (s)
A2: 1 | B2: Optique | C2: H800-Nb2O5 | D2: 532 | E2: 0 | F2: 93.226766 | G2: =E2/Paramètres!$B$3 | H2: =0+G2
A3: 1 | B3: Optique | C3: H800-Nb2O5 | D3: 532 | E3: 2.5 | F3: 93.019352 | G3: =E3/Paramètres!$B$3 | H3: =0+G3
A4: 1 | B4: Optique | C4: H800-Nb2O5 | D4: 532 | E4: 5 | F4: 92.406601 | G4: =E4/Paramètres!$B$3 | H4: =0+G4
A5: 1 | B5: Optique | C5: H800-Nb2O5 | D5: 532 | E5: 7.5 | F5: 91.416039 | G5: =E5/Paramètres!$B$3 | H5: =0+G5
A6: 1 | B6: Optique | C6: H800-Nb2O5 | D6: 532 | E6: 10 | F6: 90.090539 | G6: =E6/Paramètres!$B$3 | H6: =0+G6
A7: 1 | B7: Optique | C7: H800-Nb2O5 | D7: 532 | E7: 12.4 | F7: 88.553274 | G7: =E7/Paramètres!$B$3 | H7: =0+G7
A8: 1 | B8: Optique | C8: H800-Nb2O5 | D8: 532 | E8: 14.9 | F8: 86.735224 | G8: =E8/Paramètres!$B$3 | H8: =0+G8
A9: 1 | B9: Optique | C9: H800-Nb2O5 | D9: 532 | E9: 17.4 | F9: 84.758756 | G9: =E9/Paramètres!$B$3 | H9: =0+G9
A10: 1 | B10: Optique | C10: H800-Nb2O5 | D10: 532 | E10: 19.9 | F10: 82.686094 | G10: =E10/Paramètres!$B$3 | H10: =0+G10
A11: 1 | B11: Optique | C11: H800-Nb2O5 | D11: 532 | E11: 22.4 | F11: 80.575085 | G11: =E11/Paramètres!$B$3 | H11: =0+G11
A12: 1 | B12: Optique | C12: H800-Nb2O5 | D12: 532 | E12: 24.9 | F12: 78.477198 | G12: =E12/Paramètres!$B$3 | H12: =0+G12
A13: 1 | B13: Optique | C13: H800-Nb2O5 | D13: 532 | E13: 27.4 | F13: 76.436471 | G13: =E13/Paramètres!$B$3 | H13: =0+G13
... A43: 1 | B43: Optique | C43: H800-Nb2O5 | D43: 532 | E43: 99.578899 | F43: 88.353199 | G43: =E43/Paramètres!$B$3 | H43: =0+G43
A44: 2 | B44: Optique | C44: H800-SiO2 | D44: 500 | E44: 0 | F44: 92.264443 | G44: =E44/Paramètres!$B$4 | H44: =Stratégie!U2+G44
A45: 2 | B45: Optique | C45: H800-SiO2 | D45: 500 | E45: 2.1 | F45: 92.467341 | G45: =E45/Paramètres!$B$4 | H45: =Stratégie!U2+G45
A46: 2 | B46: Optique | C46: H800-SiO2 | D46: 500 | E46: 4.2 | F46: 92.670476 | G46: =E46/Paramètres!$B$4 | H46: =Stratégie!U2+G46
A47: 2 | B47: Optique | C47: H800-SiO2 | D47: 500 | E47: 6.4 | F47: 92.882156 | G47: =E47/Paramètres!$B$4 | H47: =Stratégie!U2+G47
A48: 2 | B48: Optique | C48: H800-SiO2 | D48: 500 | E48: 8.5 | F48: 93.081809 | G48: =E48/Paramètres!$B$4 | H48: =Stratégie!U2+G48
A49: 2 | B49: Optique | C49: H800-SiO2 | D49: 500 | E49: 10.6 | F49: 93.277813 | G49: =E49/Paramètres!$B$4 | H49: =Stratégie!U2+G49
A50: 2 | B50: Optique | C50: H800-SiO2 | D50: 500 | E50: 12.7 | F50: 93.468894 | G50: =E50/Paramètres!$B$4 | H50: =Stratégie!U2+G50
A51: 2 | B51: Optique | C51: H800-SiO2 | D51: 500 | E51: 14.9 | F51: 93.66243 | G51: =E51/Paramètres!$B$4 | H51: =Stratégie!U2+G51
A52: 2 | B52: Optique | C52: H800-SiO2 | D52: 500 | E52: 17 | F52: 93.839548 | G52: =E52/Paramètres!$B$4 | H52: =Stratégie!U2+G52
A53: 2 | B53: Optique | C53: H800-SiO2 | D53: 500 | E53: 19.1 | F53: 94.008012 | G53: =E53/Paramètres!$B$4 | H53: =Stratégie!U2+G53
A54: 2 | B54: Optique | C54: H800-SiO2 | D54: 500 | E54: 21.2 | F54: 94.166678 | G54: =E54/Paramètres!$B$4 | H54: =Stratégie!U2+G54
A55: 2 | B55: Optique | C55: H800-SiO2 | D55: 500 | E55: 23.3 | F55: 94.314456 | G55: =E55/Paramètres!$B$4 | H55: =Stratégie!U2+G55
A56: 2 | B56: Optique | C56: H800-SiO2 | D56: 500 | E56: 25.5 | F56: 94.456479 | G56: =E56/Paramètres!$B$4 | H56: =Stratégie!U2+G56
A57: 2 | B57: Optique | C57: H800-SiO2 | D57: 500 | E57: 27.6 | F57: 94.57885 | G57: =E57/Paramètres!$B$4 | H57: =Stratégie!U2+G57
A58: 2 | B58: Optique | C58: H800-SiO2 | D58: 500 | E58: 29.7 | F58: 94.687454 | G58: =E58/Paramètres!$B$4 | H58: =Stratégie!U2+G58
A59: 2 | B59: Optique | C59: H800-SiO2 | D59: 500 | E59: 31.8 | F59: 94.781522 | G59: =E59/Paramètres!$B$4 | H59: =Stratégie!U2+G59
A60: 2 | B60: Optique | C60: H800-SiO2 | D60: 500 | E60: 34 | F60: 94.863746 | G60: =E60/Paramètres!$B$4 | H60: =Stratégie!U2+G60
A61: 2 | B61: Optique | C61: H800-SiO2 | D61: 500 | E61: 36.1 | F61: 94.926067 | G61: =E61/Paramètres!$B$4 | H61: =Stratégie!U2+G61
A62: 2 | B62: Optique | C62: H800-SiO2 | D62: 500 | E62: 38.2 | F62: 94.972139 | G62: =E62/Paramètres!$B$4 | H62: =Stratégie!U2+G62
A63: 2 | B63: Optique | C63: H800-SiO2 | D63: 500 | E63: 40.3 | F63: 95.001628 | G63: =E63/Paramètres!$B$4 | H63: =Stratégie!U2+G63
A64: 2 | B64: Optique | C64: H800-SiO2 | D64: 500 | E64: 42.4 | F64: 95.014319 | G64: =E64/Paramètres!$B$4 | H64: =Stratégie!U2+G64
A65: 2 | B65: Optique | C65: H800-SiO2 | D65: 500 | E65: 42.9 | F65: 95.014852 | G65: =E65/Paramètres!$B$4 | H65: =Stratégie!U2+G65
A66: 2 | B66: Optique | C66: H800-SiO2 | D66: 500 | E66: 44.6 | F66: 95.009499 | G66: =E66/Paramètres!$B$4 | H66: =Stratégie!U2+G66
A67: 2 | B67: Optique | C67: H800-SiO2 | D67: 500 | E67: 46.7 | F67: 94.987638 | G67: =E67/Paramètres!$B$4 | H67: =Stratégie!U2+G67
A68: 2 | B68: Optique | C68: H800-SiO2 | D68: 500 | E68: 48.8 | F68: 94.949077 | G68: =E68/Paramètres!$B$4 | H68: =Stratégie!U2+G68
A69: 2 | B69: Optique | C69: H800-SiO2 | D69: 500 | E69: 50.9 | F69: 94.894092 | G69: =E69/Paramètres!$B$4 | H69: =Stratégie!U2+G69
...

Sheet Spectres finaux
A1: λ (nm) | B1: Pièce et témoin, T (%) | C1: Cible T (%) (400-729 nm)
A2: 380 | B2: 0.0011971027
A3: 381 | B3: 0.011611393
A4: 382 | B4: 0.85240457
A5: 383 | B5: 0.011564107
A6: 384 | B6: 0.0039832866
A7: 385 | B7: 0.043575955
A8: 386 | B8: 0.0030077491
A9: 387 | B9: 0.00092356779
A10: 388 | B10: 0.0010623228
A11: 389 | B11: 0.0020062796
A12: 390 | B12: 0.0025229231
A13: 391 | B13: 0.0038505575
... A21: 399 | B21: 0.59336769
A22: 400 | B22: 0.851428 | C22: 0
A23: 401 | B23: 0.68474181 | C23: 0
A24: 402 | B24: 0.21368516 | C24: 0
A25: 403 | B25: 0.17667974 | C25: 0
A26: 404 | B26: 0.37144483 | C26: 0.97437662
A27: 405 | B27: 2.4825457 | C27: 3.2609635
A28: 406 | B28: 12.798878 | C28: 11.943031
A29: 407 | B29: 11.229004 | C29: 12
A30: 408 | B30: 13.888628 | C30: 12
A31: 409 | B31: 10.190561 | C31: 12
A32: 410 | B32: 12.121324 | C32: 12
A33: 411 | B33: 12.799224 | C33: 12
... A350: 728 | B350: 0.00015600397 | C350: 0
A351: 729 | B351: 0.00014576155
A352: 730 | B352: 0.00014165494
A353: 731 | B353: 0.00014360734
A354: 732 | B354: 0.00015226642
A355: 733 | B355: 0.00016935417
A356: 734 | B356: 0.00019845168
A357: 735 | B357: 0.00024656628
A358: 736 | B358: 0.00032809812
A359: 737 | B359: 0.00047511874
A360: 738 | B360: 0.0007701885
A361: 739 | B361: 0.0014753784
A362: 740 | B362: 0.003798968
... A522: 900 | B522: 14.812988

Sheet Indices
A1: λ (nm) | B1: n H800-Nb2O5 | C1: k H800-Nb2O5 | D1: n H800-SiO2 | E1: k H800-SiO2 | F1: n Silice fondue (CERTUS id 0) | G1: k Silice fondue (CERTUS id 0)
A2: 400 | B2: 2.53619 | C2: 5.4e-05 | D2: 1.5000615 | E2: 6.8e-05 | F2: 1.4701161 | G2: 0
A3: 405 | B3: 2.5245735 | C3: 2.4e-05 | D3: 1.499362 | E3: 6.6e-05 | F3: 1.469581 | G3: 0
A4: 410 | B4: 2.513734 | C4: 1e-05 | D4: 1.498688 | E4: 6.4e-05 | F4: 1.4690663 | G4: 0
A5: 415 | B5: 2.503628 | C5: 4.5e-06 | D5: 1.4980398 | E5: 6.25e-05 | F5: 1.4685709 | G5: 0
A6: 420 | B6: 2.494119 | C6: 2e-06 | D6: 1.4974145 | E6: 6.05e-05 | F6: 1.4680937 | G6: 0
A7: 425 | B7: 2.48519 | C7: 1e-06 | D7: 1.4968135 | E7: 5.925e-05 | F7: 1.4676339 | G7: 0
A8: 430 | B8: 2.476744 | C8: 0 | D8: 1.496233 | E8: 5.8e-05 | F8: 1.4671905 | G8: 0
A9: 435 | B9: 2.468774 | C9: 0 | D9: 1.495674 | E9: 5.625e-05 | F9: 1.4667627 | G9: 0
A10: 440 | B10: 2.461205 | C10: 0 | D10: 1.4951335 | E10: 5.5e-05 | F10: 1.4663498 | G10: 0
A11: 445 | B11: 2.454036 | C11: 0 | D11: 1.494613 | E11: 5.375e-05 | F11: 1.465951 | G11: 0
A12: 450 | B12: 2.447206 | C12: 0 | D12: 1.4941095 | E12: 5.25e-05 | F12: 1.4655657 | G12: 0
A13: 455 | B13: 2.440717 | C13: 0 | D13: 1.4936235 | E13: 5.125e-05 | F13: 1.4651931 | G13: 0
... A102: 900 | B102: 2.264553 | C102: 0 | D102: 1.477741 | E102: 2.3e-05 | F102: 1.451754 | G102: 0
A104: Convention n̂ = n − ik (k ≥ 0). Couches : example/database_index/indices.xlsx (base CERTUS) ; silice : substrat id 0 de CERTUS.

Sheet Cible et nominal
A1: λ (nm) | B1: Cible T (%) | C1: Pièce nominale T (%) | D1: Écart (pp)
A2: 400 | B2: 0 | C2: 0.851428 | D2: 0.851428
A3: 400.40027 | B3: 0 | C3: 1.0888515 | D3: 1.0888515
A4: 400.80094 | B4: 0 | C4: 0.89035748 | D4: 0.89035748
A5: 401.20201 | B5: 0 | C5: 0.51023236 | D5: 0.51023236
A6: 401.60348 | B6: 0 | C6: 0.30395607 | D6: 0.30395607
A7: 402.00535 | B7: 0 | C7: 0.21292071 | D7: 0.21292071
A8: 402.40762 | B8: 0 | C8: 0.17644685 | D8: 0.17644685
A9: 402.81029 | B9: 0 | C9: 0.17055348 | D9: 0.17055348
A10: 403.21336 | B10: 0 | C10: 0.19113608 | D10: 0.19113608
A11: 403.61683 | B11: 0.5 | C11: 0.24890015 | D11: -0.25109985
A12: 404.0207 | B12: 1 | C12: 0.38122102 | D12: -0.61877898
A13: 404.42507 | B13: 1.5 | C13: 0.70181592 | D13: -0.79818408
... A602: 728.84959 | B602: 0 | C602: 0.00014690127 | D602: 0.00014690127
